Workbook

Sheet README
A1: Project Southeast Asia - v2 Valuation (post-announcement)
A2: Independent student analysis/reconstruction based on publicly available information. Not affiliated with, commissioned by, or representative of Goldman Sachs, AkzoNobel or Nippon Paint.
A4: PURPOSE: apply comps, precedents and the v2 DCF to the REPORTED FY2025 (and Base FY2026E) financials of the seven-country perimeter, triangulate, then check against the announced EUR 1.2bn. The announced price is a CHECK, not a target.
A5: SHEETS: Comps (reused from 03_Trading_Comps, pulled 2026-09-18, not refreshed) | Precedents (four existing + announced deal as an EXCLUDED reference row) | Implied_Valuation | Triangulation (weights fixed first) | Deal_Check (gaps, reverse DCF, leakage).
A6: LINK CHOICE: model outputs are PASTED VALUES in red font, each labelled with its source cell in Project_Southeast_Asia_v2_Financial_Model.xlsx, rather than live external links (script-built external links trigger Excel update prompts and break if the folder moves). A scripted check confirms every pasted value equals the model cell. Re-run the build after any model change.
A7: WEIGHTS: fixed on Triangulation before the comparison on Deal_Check, with the logic stated; alternatives are shown for transparency, not selected.
A8: LIMITATIONS: FY24/FY25 financials come from media reports (reported by several outlets, attributed to Nippon Paint; primary release not read), not in AkzoNobel's release; the 2026 projection is single-source; country split and country risk premiums are illustrative; comps are dated 2026-09-18; the Information Memorandum and pitch deck valuation slides have NOT been refreshed.
A9: COLOUR CODE: blue = input; black = formula; green = same-workbook link; red = value copied from the model workbook.

Sheet Comps
A1: Trading comparables (REUSED from 03_Trading_Comps: same pull date, same method, not refreshed)
A2: Yahoo Finance (yfinance) single pull, 2026-09-18 (SRC-034). Native-currency millions; multiples are unit-free. Inputs copied from 03_Trading_Comps; statistics recomputed here.
A4: Company | B4: Ccy | C4: Enterprise value | D4: Revenue TTM | E4: EBITDA TTM | F4: EBITDA margin | G4: EV / Revenue | H4: EV / EBITDA | I4: In statistics?
A5: Sherwin-Williams | B5: USD | C5: 92316.5 | D5: 24410.3 | E5: 4709.1 | F5: =E5/D5 -> 0.19291447 | G5: =C5/D5 -> 3.7818667 | H5: =C5/E5 -> 19.603852 | I5: Yes
A6: PPG Industries | B6: USD | C6: 29345.1 | D6: 16421 | E6: 2698 | F6: =E6/D6 -> 0.16430181 | G6: =C6/D6 -> 1.7870471 | H6: =C6/E6 -> 10.876612 | I6: Yes
A7: Nippon Paint Holdings | B7: JPY | C7: 3641233.6 | D7: 1945486 | E7: 361080 | F7: =E7/D7 -> 0.18559887 | G7: =C7/D7 -> 1.8716319 | H7: =C7/E7 -> 10.084285 | I7: Yes
A8: Kansai Paint | B8: JPY | C8: 701160.3 | D8: 602968 | E8: 77297.7 | F8: =E8/D8 -> 0.12819536 | G8: =C8/D8 -> 1.1628483 | H8: =C8/E8 -> 9.0709077 | I8: Yes
A9: Asian Paints | B9: INR | C9: 2313578.1 | D9: 371869.3 | E9: 68878.9 | F9: =E9/D9 -> 0.18522341 | G9: =C9/D9 -> 6.2214818 | H9: =C9/E9 -> 33.589069 | I9: Yes
A10: Berger Paints India | B10: INR | C10: 516758.2 | D10: 122632.4 | E10: 18228.5 | F10: =E10/D10 -> 0.14864343 | G10: =C10/D10 -> 4.2138799 | H10: =C10/E10 -> 28.348915 | I10: Yes
A11: AkzoNobel (AKZA.AS) — SELLER, reference only | B11: EUR | C11: 13169.4 | D11: 9894 | E11: 1068 | F11: =E11/D11 -> 0.10794421 | G11: =C11/D11 -> 1.3310491 | H11: =C11/E11 -> 12.330899 | I11: No (seller, reference)
A13: Statistic (rows 5-10) | G13: EV / Revenue | H13: EV / EBITDA
A14: 25th percentile | G14: =QUARTILE(G5:G10,1) -> 1.8081933 | H14: =QUARTILE(H5:H10,1) -> 10.282367
A15: Median | G15: =MEDIAN(G5:G10) -> 2.8267493 | H15: =MEDIAN(H5:H10) -> 15.240232
A16: 75th percentile | G16: =QUARTILE(G5:G10,3) -> 4.1058766 | H16: =QUARTILE(H5:H10,3) -> 26.162649
A18: Caveats: peers are listed, mostly larger and differently mixed; trading multiples are minority, TTM, in different markets. Asian Paints and Berger (28-34x EBITDA) pull the upper quartile far above the rest. Not refreshed after the 5 Oct 2026 announcement.

Sheet Precedents
A1: Precedent transactions (four REUSED from 04_Precedent_Transactions + the announced deal as a reference row)
A2: Statistics use rows 5-8 only. The announced deal (row 10) is shown for reference and EXCLUDED, so the check against it is not circular.
A4: Transaction | B4: Ccy | C4: EV (m) | D4: Revenue (m) | E4: EBITDA (m) | F4: EV / Revenue | G4: EV / EBITDA | H4: Classification / note
A5: PPG Architectural Coatings (US/Canada) -> AIP, 2024 | B5: USD | C5: 550 | D5: 2000 | F5: =C5/D5 -> 0.275 | H5: EV and revenue DISCLOSED; EBITDA UNAVAILABLE. Sponsor buyer.
A6: Suvinil (BASF Brazil) -> Sherwin-Williams, 2025 | B6: USD | C6: 1150 | D6: 525 | F6: =C6/D6 -> 2.1904762 | H6: EV/revenue ANALYST CALCULATION; 'low teens' EBITDA is qualitative only -> UNAVAILABLE here.
A7: AkzoNobel Decorative (global) <- Nippon Paint offer, 2026 | B7: EUR | C7: 7500 | D7: 4090 | E7: =D7*0.158 -> 646.22 | F7: =C7/D7 -> 1.8337408 | G7: =C7/E7 -> 11.605955 | H7: REJECTED offer, not a completed deal. EBITDA = revenue x 15.8% (ANALYST CALCULATION).
A8: AkzoNobel India -> JSW Paints, 2025 | B8: EUR | G8: 25 | H8: EV/EBITDA 25x DISCLOSED; EV/revenue UNAVAILABLE. Controlling stake in a single, high-growth Indian market.
A10: Announced deal (reference only, EXCLUDED): SE Asia Decorative Paints -> Nippon Paint, Oct 2026 | B10: USD | C10: 1350 | D10: 291 | E10: 65 | F10: =C10/D10 -> 4.6391753 | G10: =C10/E10 -> 20.769231 | H10: EV: PUBLIC FACT (SRC-037). Revenue/EBITDA: REPORTED, corroborated. Pasted from model Assumptions cells ev_usd, rev25_usd, ebitda25_usd.
A12: Statistic (rows 5-8 only) | F12: EV / Revenue | G12: EV / EBITDA
A13: Minimum | F13: =MIN(F5:F8) -> 0.275 | G13: =MIN(G5:G8) -> 11.605955
A14: Median | F14: =MEDIAN(F5:F8) -> 1.8337408 | G14: =MEDIAN(G5:G8) -> 18.302977
A15: Maximum | F15: =MAX(F5:F8) -> 2.1904762 | G15: =MAX(G5:G8) -> 25
A16: Count of data points | F16: =COUNT(F5:F8) -> 3 | G16: =COUNT(G5:G8) -> 2
A17: EV/EBITDA rests on only two data points (a rejected offer and a controlling Indian stake); EV/revenue on three, one a sponsor deal in North America. Weights in Triangulation reflect this.

Sheet Implied_Valuation
A1: Implied valuation: multiples applied to reported FY2025 and Base FY2026E metrics (EUR m)
A2: Metrics are pasted values from the v2 model (red font); the last column names the source cell.
A4: Metric (EUR m) | B4: Value | G4: Source: v2 model cell
A5: FY2025 reported revenue | B5: 258.66667 | G5: Assumptions!B26
A6: FY2025 reported EBITDA | B6: 57.777778 | G6: Assumptions!B28
A7: FY2026E revenue, Base case | B7: 271.6 | G7: Cases!B17
A8: FY2026E EBITDA, Base case | B8: 60.666667 | G8: Cases!B19
A11: Multiples used
A12: Method | B12: Metric | C12: Low | D12: Mid | E12: High
A13: Trading comps EV/EBITDA (P25 / median / P75) x FY25 EBITDA | B13: =B6 -> 57.777778 | C13: =Comps!H14 -> 10.282367 | D13: =Comps!H15 -> 15.240232 | E13: =Comps!H16 -> 26.162649
A14: Trading comps EV/EBITDA x FY26E Base EBITDA | B14: =B8 -> 60.666667 | C14: =Comps!H14 -> 10.282367 | D14: =Comps!H15 -> 15.240232 | E14: =Comps!H16 -> 26.162649
A15: Trading comps EV/Revenue (P25 / median / P75) x FY25 revenue | B15: =B5 -> 258.66667 | C15: =Comps!G14 -> 1.8081933 | D15: =Comps!G15 -> 2.8267493 | E15: =Comps!G16 -> 4.1058766
A16: Trading comps EV/Revenue x FY26E Base revenue | B16: =B7 -> 271.6 | C16: =Comps!G14 -> 1.8081933 | D16: =Comps!G15 -> 2.8267493 | E16: =Comps!G16 -> 4.1058766
A17: Precedents EV/EBITDA (min / median / max) x FY25 EBITDA | B17: =B6 -> 57.777778 | C17: =Precedents!G13 -> 11.605955 | D17: =Precedents!G14 -> 18.302977 | E17: =Precedents!G15 -> 25
A18: Precedents EV/EBITDA x FY26E Base EBITDA | B18: =B8 -> 60.666667 | C18: =Precedents!G13 -> 11.605955 | D18: =Precedents!G14 -> 18.302977 | E18: =Precedents!G15 -> 25
A19: Precedents EV/Revenue (min / median / max) x FY25 revenue | B19: =B5 -> 258.66667 | C19: =Precedents!F13 -> 0.275 | D19: =Precedents!F14 -> 1.8337408 | E19: =Precedents!F15 -> 2.1904762
A20: Precedents EV/Revenue x FY26E Base revenue | B20: =B7 -> 271.6 | C20: =Precedents!F13 -> 0.275 | D20: =Precedents!F14 -> 1.8337408 | E20: =Precedents!F15 -> 2.1904762
A22: Implied enterprise value (EUR m)
A23: Method | C23: Low | D23: Mid | E23: High
A24: Trading comps EV/EBITDA (P25 / median / P75) x FY25 EBITDA | C24: =$B13*C13 -> 594.0923 | D24: =$B13*D13 -> 880.54675 | E24: =$B13*E13 -> 1511.6197
A25: Trading comps EV/EBITDA x FY26E Base EBITDA | C25: =$B14*C14 -> 623.79692 | D25: =$B14*D14 -> 924.57409 | E25: =$B14*E14 -> 1587.2007
A26: Trading comps EV/Revenue (P25 / median / P75) x FY25 revenue | C26: =$B15*C15 -> 467.71933 | D26: =$B15*D15 -> 731.18581 | E26: =$B15*E15 -> 1062.0534
A27: Trading comps EV/Revenue x FY26E Base revenue | C27: =$B16*C16 -> 491.10529 | D27: =$B16*D16 -> 767.7451 | E27: =$B16*E16 -> 1115.1561
A28: Precedents EV/EBITDA (min / median / max) x FY25 EBITDA | C28: =$B17*C17 -> 670.56627 | D28: =$B17*D17 -> 1057.5054 | E28: =$B17*E17 -> 1444.4444
A29: Precedents EV/EBITDA x FY26E Base EBITDA | C29: =$B18*C18 -> 704.09458 | D29: =$B18*D18 -> 1110.3806 | E29: =$B18*E18 -> 1516.6667
A30: Precedents EV/Revenue (min / median / max) x FY25 revenue | C30: =$B19*C19 -> 71.133333 | D30: =$B19*D19 -> 474.32763 | E30: =$B19*E19 -> 566.60317
A31: Precedents EV/Revenue x FY26E Base revenue | C31: =$B20*C20 -> 74.69 | D31: =$B20*D20 -> 498.04401 | E31: =$B20*E20 -> 594.93333
A33: Low / Mid / High are percentile or min / median / max picks, not scenarios. EV/revenue ignores margin; EV/EBITDA ignores growth. Rows 24, 26, 28, 30 (FY25) feed Triangulation.

Sheet Triangulation
A1: Valuation triangulation (EUR m)
A2: WEIGHTS ARE FIXED HERE, ON FIRST PRINCIPLES, BEFORE ANY COMPARISON WITH THE ANNOUNCED PRICE (Deal_Check). They were not adjusted after seeing the gap.
A4: Weighting logic (stated before comparison)
A5: 1. Intrinsic value (DCF) carries 40%: the only method built on this business's own reported margin and an explicit risk-adjusted discount rate. Split Base 25% / Buyer 7.5% / Downside 7.5%: Base is the seller / standalone view; the other two bracket it.
A6: 2. Market EV/EBITDA methods carry the next weight: trading comps 25% (six listed peers, one date) and precedents 15% (only two data points, one a rejected offer).
A7: 3. EV/Revenue methods carry 10% each: revenue multiples ignore the ~22% margin and range widely (0.3x to 6.2x), so they are context, not anchors.
A8: 4. Weights sum to 100% and are held constant. Deal_Check shows alternative weightings for transparency; none was chosen after seeing the result.
A10: Method | B10: Weight | C10: Low | D10: Mid | E10: High | G10: Basis
A11: DCF - Base case | B11: 0.25 | C11: 618.1059 | D11: 712.65341 | E11: 845.99667 | G11: Seller / standalone: reported FY25 margin held, 5% growth. Pasted from model Cases B37 / B35 / B38; Low/High = WACC +/- 0.5pp with g -/+ 0.5pp
A12: DCF - Buyer case | B12: 0.075 | C12: 741.2877 | D12: 853.74496 | E12: 1012.3308 | G12: Nippon Paint's 2026 projection (single-source, buyer's view), then a fade. Pasted from model Cases B68 / B66 / B69; Low/High = WACC +/- 0.5pp with g -/+ 0.5pp
A13: DCF - Downside case | B13: 0.075 | C13: 509.65832 | D13: 586.19842 | E13: 694.09726 | G13: 3% growth, margin step-down for standalone costs. Pasted from model Cases B99 / B97 / B100; Low/High = WACC +/- 0.5pp with g -/+ 0.5pp
A14: Trading comps - EV/EBITDA (FY25 reported) | B14: 0.25 | C14: =Implied_Valuation!C24 -> 594.0923 | D14: =Implied_Valuation!D24 -> 880.54675 | E14: =Implied_Valuation!E24 -> 1511.6197 | G14: P25 / median / P75 of six peers
A15: Trading comps - EV/Revenue (FY25 reported) | B15: 0.1 | C15: =Implied_Valuation!C26 -> 467.71933 | D15: =Implied_Valuation!D26 -> 731.18581 | E15: =Implied_Valuation!E26 -> 1062.0534 | G15: P25 / median / P75 of six peers
A16: Precedents - EV/EBITDA (FY25 reported) | B16: 0.15 | C16: =Implied_Valuation!C28 -> 670.56627 | D16: =Implied_Valuation!D28 -> 1057.5054 | E16: =Implied_Valuation!E28 -> 1444.4444 | G16: min / median / max, 2 data points
A17: Precedents - EV/Revenue (FY25 reported) | B17: 0.1 | C17: =Implied_Valuation!C30 -> 71.133333 | D17: =Implied_Valuation!D30 -> 474.32763 | E17: =Implied_Valuation!E30 -> 566.60317 | G17: min / median / max, 3 data points
A18: Total weight (check = 100%) | B18: =SUM(B11:B17) -> 1
A19: Weighted enterprise value (EUR m) | C19: =SUMPRODUCT($B$11:$B$17,C11:C17) -> 551.34071 | D19: =SUMPRODUCT($B$11:$B$17,D11:D17) -> 785.47294 | E19: =SUMPRODUCT($B$11:$B$17,E11:E17) -> 1096.9185
A20: Recommended range, rounded to EUR 25m: low / mid / high | C20: =MROUND(C19,25) -> 550 | D20: =MROUND(D19,25) -> 775 | E20: =MROUND(E19,25) -> 1100
A21: Mid-point implied EV / FY2025 reported EBITDA | D21: =D20/Implied_Valuation!B6 -> 13.413462
A22: Check: Base DCF mid here less the model value (must be 0) | D22: =D11-712.653406213068 -> 0
A24: The range is a weighted blend, not a forecast of the sale price. The September (pre-announcement) range was EUR 500 / 625 / 775m on a four-country basis and a different revenue anchor; the two are not like-for-like.

Sheet Deal_Check
A1: Deal check: our methods versus the announced price (a CHECK, not a target)
A2: Nothing in the model or the weights was changed after this sheet was designed. Gaps are reported as they fall.
A4: Announced transaction and inputs | B4: Value | F4: Source
A5: Announced EV (EUR m) | B5: 1200 | F5: AkzoNobel release (SRC-037) - PUBLIC FACT
A6: Announced EV (USD m) | B6: 1350 | F6: SRC-037
A7: FX, USD per EUR | B7: 1.125 | F7: model Assumptions: the single FX input
A8: FY2025 reported EBITDA (EUR m) | B8: 57.777778 | F8: REPORTED, corroborated; model cell
A9: FY2025 reported revenue (EUR m) | B9: 258.66667 | F9: REPORTED, corroborated; model cell
A10: Base FY2026E EBITDA (EUR m) | B10: 60.666667 | F10: model Cases (Base)
A11: Buyer FY2026E EBITDA (EUR m) | B11: 76.266667 | F11: model Cases (Buyer; = Nippon Paint's projection)
A12: Net cash proceeds (EUR m) | B12: 900 | F12: AkzoNobel release (SRC-037)
A14: Implied multiples at the announced price
A15: EV / FY2025 reported EBITDA (AkzoNobel states 21x) | B15: =B5/B8 -> 20.769231
A16: EV / Base FY2026E EBITDA | B16: =B5/B10 -> 19.78022
A17: EV / Buyer FY2026E EBITDA (Nippon Paint states ~16x) | B17: =B5/B11 -> 15.734266
A18: EV / FY2025 reported revenue | B18: =B5/B9 -> 4.6391753
A20: Gap of each method versus the announced EV (mid-points; EUR m and %)
A21: Method | B21: Weight | C21: Our mid EV | D21: Gap: announced less ours | E21: Announced / ours - 1
A22: =Triangulation!A11 -> DCF - Base case | B22: =Triangulation!B11 -> 0.25 | C22: =Triangulation!D11 -> 712.65341 | D22: =$B$5-C22 -> 487.34659 | E22: =$B$5/C22-1 -> 0.68384798
A23: =Triangulation!A12 -> DCF - Buyer case | B23: =Triangulation!B12 -> 0.075 | C23: =Triangulation!D12 -> 853.74496 | D23: =$B$5-C23 -> 346.25504 | E23: =$B$5/C23-1 -> 0.40557199
A24: =Triangulation!A13 -> DCF - Downside case | B24: =Triangulation!B13 -> 0.075 | C24: =Triangulation!D13 -> 586.19842 | D24: =$B$5-C24 -> 613.80158 | E24: =$B$5/C24-1 -> 1.0470884
A25: =Triangulation!A14 -> Trading comps - EV/EBITDA (FY25 reported) | B25: =Triangulation!B14 -> 0.25 | C25: =Triangulation!D14 -> 880.54675 | D25: =$B$5-C25 -> 319.45325 | E25: =$B$5/C25-1 -> 0.36278965
A26: =Triangulation!A15 -> Trading comps - EV/Revenue (FY25 reported) | B26: =Triangulation!B15 -> 0.1 | C26: =Triangulation!D15 -> 731.18581 | D26: =$B$5-C26 -> 468.81419 | E26: =$B$5/C26-1 -> 0.6411697
A27: =Triangulation!A16 -> Precedents - EV/EBITDA (FY25 reported) | B27: =Triangulation!B16 -> 0.15 | C27: =Triangulation!D16 -> 1057.5054 | D27: =$B$5-C27 -> 142.49464 | E27: =$B$5/C27-1 -> 0.13474603
A28: =Triangulation!A17 -> Precedents - EV/Revenue (FY25 reported) | B28: =Triangulation!B17 -> 0.1 | C28: =Triangulation!D17 -> 474.32763 | D28: =$B$5-C28 -> 725.67237 | E28: =$B$5/C28-1 -> 1.5298969
A29: Weighted triangulation (recommended mid) | C29: =Triangulation!D19 -> 785.47294 | D29: =$B$5-C29 -> 414.52706 | E29: =$B$5/C29-1 -> 0.527742
A30: Where the announced EV falls against the weighted low / high | C30: =IF($B$5>Triangulation!E19,"above the high end",IF($B$5<Triangulation!C19,"below the low end","inside the range")) -> above the high end
A31: Highest / lowest single-method mid-point (EUR m) | C31: =MAX(C22:C28) -> 1057.5054 | D31: =MIN(C22:C28) -> 474.32763
A32: Methods (of 7) whose HIGH value reaches the announced EV | C32: =SUMPRODUCT(--(Triangulation!E11:E17>=B5)) -> 2
A34: Sensitivity of the conclusion to the weights (stated alternatives, none selected)
A35: Weighting scheme | C35: Weighted mid EV | D35: Gap: announced less ours | E35: Announced / ours - 1
A36: As fixed on Triangulation | C36: =0.25*C22+0.075*C23+0.075*C24+0.25*C25+0.1*C26+0.15*C27+0.1*C28 -> 785.47294 | D36: =$B$5-C36 -> 414.52706 | E36: =$B$5/C36-1 -> 0.527742
A37: Equal weight, all seven methods | C37: =0.142857*C22+0.142857*C23+0.142857*C24+0.142857*C25+0.142857*C26+0.142857*C27+0.142857*C28 -> 756.59386 | D37: =$B$5-C37 -> 443.40614 | E37: =$B$5/C37-1 -> 0.58605569
A38: DCF only (Base 50% / Buyer 25% / Downside 25%) | C38: =0.5*C22+0.25*C23+0.25*C24 -> 716.31255 | D38: =$B$5-C38 -> 483.68745 | E38: =$B$5/C38-1 -> 0.67524638
A39: Market only (EV/EBITDA 60%, EV/Revenue 40%; comps and precedents equal) | C39: =0.3*C25+0.2*C26+0.3*C27+0.2*C28 -> 822.51832 | D39: =$B$5-C39 -> 377.48168 | E39: =$B$5/C39-1 -> 0.45893407
A41: Reverse DCF (pasted from the v2 model Cases sheet)
A42: What you need to believe to reach the announced EV (other inputs held) | B42: Base | C42: Buyer | D42: Downside
A43: Terminal EBITDA margin needed | B43: 0.38670819 | C43: 0.3491373 | D43: 0.42985523
A44: Terminal growth needed (WACC held) | B44: 0.057161296 | C44: 0.049949865 | D44: 0.063626374
A45: Case terminal EBITDA margin (FY2030E) | B45: 0.2233677 | C45: 0.24168385 | D45: 0.2033677
...
