Workbook

Sheet README
A1: Project Southeast Asia — Carve-Out Financial Model
A2: Independent student analysis/reconstruction based on publicly available information. Not affiliated with, commissioned by, or representative of Goldman Sachs or AkzoNobel.
A4: SCOPE: This model reconstructs a carve-out P&L and unlevered DCF for AkzoNobel's reported Southeast Asian decorative paints operations (Indonesia, Thailand, Malaysia, Vietnam), based on the single public revenue data point disclosed by ION Analytics (EUR 300m annual revenue) and the asset perimeter mapped in 01_Source_Data/SEA_Asset_Perimeter.xlsx.
A6: CRITICAL LIMITATION: AkzoNobel does not publicly disclose SEA-decorative-specific EBITDA, margins, working capital, capex, D&A, or country-level revenue splits. Every line in this model beyond the single EUR 300m revenue anchor and the four countries' statutory tax rates is therefore either an ANALYST CALCULATION built from that anchor, or an ILLUSTRATIVE ASSUMPTION. This is disclosed on every tab via the color/classification legend below and documented cell-by-cell in the Assumptions tab and Support_Assumptions.xlsx (09_Assumptions).
A8: COLOR LEGEND:
A9: Blue text = hardcoded input / assumption (see Assumptions tab for source and rationale)
A10: Black text = formula calculated within this workbook
A11: Green text = link to another sheet in this workbook
A12: Yellow fill = key assumption the reader should scrutinize first
A14: HISTORICAL PERIOD (FY2023-FY2025): AkzoNobel has not disclosed SEA-decorative historical financials. The FY2025 revenue figure (EUR 300m) is the one public data point (ION Analytics, reported in the context of the CEO's April 2026 comments). FY2023 and FY2024 are back-solved from FY2025 using an ILLUSTRATIVE historical growth assumption anchored to ASEAN paints market growth — they are not observed historical actuals and should not be cited as such.
A16: EBITDA MARGIN: FY2024 (14.2%) and FY2025 (15.8%) margin assumptions are set equal to AkzoNobel's ACTUAL, PUBLICLY DISCLOSED GLOBAL Decorative Paints segment EBITDA margin (source: AkzoNobel FY2025 results release) as a starting proxy — this is a modeling choice, not a confirmed SEA-specific figure, since no SEA-only margin is disclosed. Forward margin assumptions ramp modestly above the group average toward regional peer levels (Nippon Paint ~18%, Asian Paints ~19-21%), reflecting SEA's higher-growth market profile — this is explicitly an ILLUSTRATIVE ASSUMPTION, not a disclosed target.
A18: TAX: Country statutory corporate income tax rates (Indonesia 22%, Thailand 20%, Malaysia 24%, Vietnam 20%) are PUBLIC FACTS (OECD / Tax Foundation / PwC tax summaries, 2026). The blended effective rate applied to the carve-out is an ANALYST CALCULATION (revenue-weighted average of the four statutory rates) — it does not reflect any AkzoNobel-specific effective tax rate, incentives, or holding structure, which are not disclosed.
... A22: See 09_Assumptions/Support_Assumptions.xlsx for the consolidated assumptions book and 10_Supporting_Research/Support_Sources.xlsx for the full source log (source IDs).

Sheet Assumptions
A1: Assumptions
A2: All inputs used across the model. Blue = hardcoded input. See Classification and Rationale columns for support.
A4: Assumption | B4: Value | C4: Classification | D4: Source / Rationale
A6: 1. Transaction Anchor
A7: FY2025 SEA Decorative Paints revenue (EUR mm) | B7: 300 | C7: PUBLIC FACT | D7: ION Analytics, 'AkzoNobel taps Goldman Sachs for sale of Southeast Asia paints assets' (SRC-001). Treated as the FY2025 (last full year) revenue base for this model.
A8: Implied EUR/USD (as reported in source) | B8: 1.153 | C8: PUBLIC FACT | D8: ION article states EUR 300m approx. USD 346m; 346/300 = 1.153.
A10: 2. Country Revenue Split (ILLUSTRATIVE ASSUMPTION)
A11: Indonesia % of SEA revenue | B11: 0.4 | C11: ILLUSTRATIVE ASSUMPTION | D11: Largest ASEAN economy/population and largest confirmed AkzoNobel decorative footprint (Tangerang site) per 01_Source_Data/SEA_Asset_Perimeter.xlsx. No disclosed country split exists.
A12: Thailand % of SEA revenue | B12: 0.25 | C12: ILLUSTRATIVE ASSUMPTION | D12: Second-largest confirmed footprint (AkzoNobel entered Thailand 1963; Bangkok decorative site).
A13: Vietnam % of SEA revenue | B13: 0.2 | C13: ILLUSTRATIVE ASSUMPTION | D13: Ben Cat, Binh Duong is AkzoNobel's largest single site in Vietnam (100m litre capacity); fast-growing market.
A14: Malaysia % of SEA revenue | B14: 0.15 | C14: ILLUSTRATIVE ASSUMPTION | D14: Smallest of the four confirmed markets by population/construction spend; site-level detail unconfirmed.
A15: Check: sum of country splits | B15: =SUM(B11:B14)
A17: 3. Revenue Growth (ILLUSTRATIVE — anchored to ASEAN paints market CAGR ~5.0%, 2026-2031, per ION article market-size figures)
A18: FY2024 growth (backward-implied, historical) | B18: 0.045 | C18: ILLUSTRATIVE ASSUMPTION | D18: ASEAN paints & coatings market projected to grow from USD 7.78bn (2026) to USD 9.92bn (2031), an implied ~5.0% CAGR (ION Analytics article). Applied uniformly across countries as a simplifying assumption.
A19: FY2025 growth (backward-implied, historical) | B19: 0.048 | C19: ILLUSTRATIVE ASSUMPTION | D19: ASEAN paints & coatings market projected to grow from USD 7.78bn (2026) to USD 9.92bn (2031), an implied ~5.0% CAGR (ION Analytics article). Applied uniformly across countries as a simplifying assumption.
A20: FY2026E growth | B20: 0.05 | C20: ILLUSTRATIVE ASSUMPTION | D20: ASEAN paints & coatings market projected to grow from USD 7.78bn (2026) to USD 9.92bn (2031), an implied ~5.0% CAGR (ION Analytics article). Applied uniformly across countries as a simplifying assumption.
A21: FY2027E growth | B21: 0.052 | C21: ILLUSTRATIVE ASSUMPTION | D21: ASEAN paints & coatings market projected to grow from USD 7.78bn (2026) to USD 9.92bn (2031), an implied ~5.0% CAGR (ION Analytics article). Applied uniformly across countries as a simplifying assumption.
A22: FY2028E growth | B22: 0.05 | C22: ILLUSTRATIVE ASSUMPTION | D22: ASEAN paints & coatings market projected to grow from USD 7.78bn (2026) to USD 9.92bn (2031), an implied ~5.0% CAGR (ION Analytics article). Applied uniformly across countries as a simplifying assumption.
A23: FY2029E growth | B23: 0.048 | C23: ILLUSTRATIVE ASSUMPTION | D23: ASEAN paints & coatings market projected to grow from USD 7.78bn (2026) to USD 9.92bn (2031), an implied ~5.0% CAGR (ION Analytics article). Applied uniformly across countries as a simplifying assumption.
A24: FY2030E growth | B24: 0.046 | C24: ILLUSTRATIVE ASSUMPTION | D24: ASEAN paints & coatings market projected to grow from USD 7.78bn (2026) to USD 9.92bn (2031), an implied ~5.0% CAGR (ION Analytics article). Applied uniformly across countries as a simplifying assumption.
A26: 4. Margins (ILLUSTRATIVE — FY2024/FY2025 anchored to AkzoNobel Group Decorative Paints actual segment margin)
A27: Gross margin % (flat, all years) | B27: 0.45 | C27: ILLUSTRATIVE ASSUMPTION | D27: Typical decorative-paints industry gross margin range; no AkzoNobel SEA-specific COGS disclosure exists.
A28: FY2023 EBITDA margin | B28: 0.13 | C28: ILLUSTRATIVE ASSUMPTION | D28: FY2023 estimated by reversing FY2024 margin trend. FY2026E+ ramps toward regional peer margins (Nippon Paint ~18%, Asian Paints ~19-21%) reflecting SEA's higher-growth market mix.
A29: FY2024 EBITDA margin (= AkzoNobel Group Decorative actual) | B29: 0.142 | C29: PUBLIC FACT (Group-level proxy) | D29: AkzoNobel FY2024/FY2025 results releases report Decorative Paints (global segment) adjusted EBITDA margin of 14.2% (2024) and 15.8% (2025) — used here as a SEA proxy since no SEA-only figure is disclosed.
A30: FY2025 EBITDA margin (= AkzoNobel Group Decorative actual) | B30: 0.158 | C30: PUBLIC FACT (Group-level proxy) | D30: AkzoNobel FY2024/FY2025 results releases report Decorative Paints (global segment) adjusted EBITDA margin of 14.2% (2024) and 15.8% (2025) — used here as a SEA proxy since no SEA-only figure is disclosed.
A31: FY2026E EBITDA margin | B31: 0.165 | C31: ILLUSTRATIVE ASSUMPTION | D31: FY2023 estimated by reversing FY2024 margin trend. FY2026E+ ramps toward regional peer margins (Nippon Paint ~18%, Asian Paints ~19-21%) reflecting SEA's higher-growth market mix.
A32: FY2027E EBITDA margin | B32: 0.17 | C32: ILLUSTRATIVE ASSUMPTION | D32: FY2023 estimated by reversing FY2024 margin trend. FY2026E+ ramps toward regional peer margins (Nippon Paint ~18%, Asian Paints ~19-21%) reflecting SEA's higher-growth market mix.
A33: FY2028E EBITDA margin | B33: 0.175 | C33: ILLUSTRATIVE ASSUMPTION | D33: FY2023 estimated by reversing FY2024 margin trend. FY2026E+ ramps toward regional peer margins (Nippon Paint ~18%, Asian Paints ~19-21%) reflecting SEA's higher-growth market mix.
A34: FY2029E EBITDA margin | B34: 0.178 | C34: ILLUSTRATIVE ASSUMPTION | D34: FY2023 estimated by reversing FY2024 margin trend. FY2026E+ ramps toward regional peer margins (Nippon Paint ~18%, Asian Paints ~19-21%) reflecting SEA's higher-growth market mix.
A35: FY2030E EBITDA margin | B35: 0.18 | C35: ILLUSTRATIVE ASSUMPTION | D35: FY2023 estimated by reversing FY2024 margin trend. FY2026E+ ramps toward regional peer margins (Nippon Paint ~18%, Asian Paints ~19-21%) reflecting SEA's higher-growth market mix.
A37: 5. Carve-Out Cost Bridge (ILLUSTRATIVE)
A38: TSA cost % of revenue — FY2023 | B38: 0 | C38: ILLUSTRATIVE ASSUMPTION | D38: Transition Services Agreement cost assumed at 3.0% of revenue in first full carve-out year (FY2026E), halving in FY2027E, and eliminated from FY2028E as standalone systems (IT, finance, HR, procurement) are built out. No AkzoNobel-specific TSA terms are publicly disclosed.
A39: TSA cost % of revenue — FY2024 | B39: 0 | C39: ILLUSTRATIVE ASSUMPTION | D39: Transition Services Agreement cost assumed at 3.0% of revenue in first full carve-out year (FY2026E), halving in FY2027E, and eliminated from FY2028E as standalone systems (IT, finance, HR, procurement) are built out. No AkzoNobel-specific TSA terms are publicly disclosed.
A40: TSA cost % of revenue — FY2025 | B40: 0 | C40: ILLUSTRATIVE ASSUMPTION | D40: Transition Services Agreement cost assumed at 3.0% of revenue in first full carve-out year (FY2026E), halving in FY2027E, and eliminated from FY2028E as standalone systems (IT, finance, HR, procurement) are built out. No AkzoNobel-specific TSA terms are publicly disclosed.
A41: TSA cost % of revenue — FY2026E | B41: 0.03 | C41: ILLUSTRATIVE ASSUMPTION | D41: Transition Services Agreement cost assumed at 3.0% of revenue in first full carve-out year (FY2026E), halving in FY2027E, and eliminated from FY2028E as standalone systems (IT, finance, HR, procurement) are built out. No AkzoNobel-specific TSA terms are publicly disclosed.
A42: TSA cost % of revenue — FY2027E | B42: 0.015 | C42: ILLUSTRATIVE ASSUMPTION | D42: Transition Services Agreement cost assumed at 3.0% of revenue in first full carve-out year (FY2026E), halving in FY2027E, and eliminated from FY2028E as standalone systems (IT, finance, HR, procurement) are built out. No AkzoNobel-specific TSA terms are publicly disclosed.
A43: TSA cost % of revenue — FY2028E | B43: 0 | C43: ILLUSTRATIVE ASSUMPTION | D43: Transition Services Agreement cost assumed at 3.0% of revenue in first full carve-out year (FY2026E), halving in FY2027E, and eliminated from FY2028E as standalone systems (IT, finance, HR, procurement) are built out. No AkzoNobel-specific TSA terms are publicly disclosed.
A44: TSA cost % of revenue — FY2029E | B44: 0 | C44: ILLUSTRATIVE ASSUMPTION | D44: Transition Services Agreement cost assumed at 3.0% of revenue in first full carve-out year (FY2026E), halving in FY2027E, and eliminated from FY2028E as standalone systems (IT, finance, HR, procurement) are built out. No AkzoNobel-specific TSA terms are publicly disclosed.
A45: TSA cost % of revenue — FY2030E | B45: 0 | C45: ILLUSTRATIVE ASSUMPTION | D45: Transition Services Agreement cost assumed at 3.0% of revenue in first full carve-out year (FY2026E), halving in FY2027E, and eliminated from FY2028E as standalone systems (IT, finance, HR, procurement) are built out. No AkzoNobel-specific TSA terms are publicly disclosed.
A47: Stranded / standalone replacement cost % of revenue — FY2023 | B47: 0 | C47: ILLUSTRATIVE ASSUMPTION | D47: Illustrative cost of replacing parent shared-service capacity (regional finance/IT/procurement) not captured in the standalone opex build — assumed 1.0% of revenue in FY2026E-FY2027E, then nil.
...

Sheet Revenue_Build
A1: Revenue Build — SEA Decorative Paints Carve-Out
A2: All figures EUR mm unless noted. FY2023-FY2024 are back-solved from the FY2025 public anchor (see README) — not observed actuals.
A4: (EUR mm) | B4: FY2023 | C4: FY2024 | D4: FY2025 | E4: FY2026E | F4: FY2027E | G4: FY2028E | H4: FY2029E | I4: FY2030E
A5: Total SEA Decorative Revenue | B5: =C5/(1+Assumptions!$B$18) | C5: =D5/(1+Assumptions!$B$19) | D5: =Assumptions!$B$7 | E5: =D5*(1+Assumptions!$B$20) | F5: =E5*(1+Assumptions!$B$21) | G5: =F5*(1+Assumptions!$B$22) | H5: =G5*(1+Assumptions!$B$23) | I5: =H5*(1+Assumptions!$B$24)
A6: Revenue growth % YoY | C6: =C5/B5-1 | D6: =D5/C5-1 | E6: =E5/D5-1 | F6: =F5/E5-1 | G6: =G5/F5-1 | H6: =H5/G5-1 | I6: =I5/H5-1
A8: Indonesia | B8: =B5*Assumptions!$B$11 | C8: =C5*Assumptions!$B$11 | D8: =D5*Assumptions!$B$11 | E8: =E5*Assumptions!$B$11 | F8: =F5*Assumptions!$B$11 | G8: =G5*Assumptions!$B$11 | H8: =H5*Assumptions!$B$11 | I8: =I5*Assumptions!$B$11
A9: Thailand | B9: =B5*Assumptions!$B$12 | C9: =C5*Assumptions!$B$12 | D9: =D5*Assumptions!$B$12 | E9: =E5*Assumptions!$B$12 | F9: =F5*Assumptions!$B$12 | G9: =G5*Assumptions!$B$12 | H9: =H5*Assumptions!$B$12 | I9: =I5*Assumptions!$B$12
A10: Vietnam | B10: =B5*Assumptions!$B$13 | C10: =C5*Assumptions!$B$13 | D10: =D5*Assumptions!$B$13 | E10: =E5*Assumptions!$B$13 | F10: =F5*Assumptions!$B$13 | G10: =G5*Assumptions!$B$13 | H10: =H5*Assumptions!$B$13 | I10: =I5*Assumptions!$B$13
A11: Malaysia | B11: =B5*Assumptions!$B$14 | C11: =C5*Assumptions!$B$14 | D11: =D5*Assumptions!$B$14 | E11: =E5*Assumptions!$B$14 | F11: =F5*Assumptions!$B$14 | G11: =G5*Assumptions!$B$14 | H11: =H5*Assumptions!$B$14 | I11: =I5*Assumptions!$B$14
A12: Check: sum of countries = Total | B12: =B8+B9+B10+B11-B5 | C12: =C8+C9+C10+C11-C5 | D12: =D8+D9+D10+D11-D5 | E12: =E8+E9+E10+E11-E5 | F12: =F8+F9+F10+F11-F5 | G12: =G8+G9+G10+G11-G5 | H12: =H8+H9+H10+H11-H5 | I12: =I8+I9+I10+I11-I5

Sheet Working_Capital
A1: Working Capital Schedule
A2: COGS = Revenue x (1 - Gross Margin %). Days assumptions per Assumptions tab, Section 7 (ILLUSTRATIVE).
A4: (EUR mm) | B4: FY2023 | C4: FY2024 | D4: FY2025 | E4: FY2026E | F4: FY2027E | G4: FY2028E | H4: FY2029E | I4: FY2030E
A5: Revenue (link) | B5: =Revenue_Build!B5 | C5: =Revenue_Build!C5 | D5: =Revenue_Build!D5 | E5: =Revenue_Build!E5 | F5: =Revenue_Build!F5 | G5: =Revenue_Build!G5 | H5: =Revenue_Build!H5 | I5: =Revenue_Build!I5
A6: COGS | B6: =B5*(1-Assumptions!$B$27) | C6: =C5*(1-Assumptions!$B$27) | D6: =D5*(1-Assumptions!$B$27) | E6: =E5*(1-Assumptions!$B$27) | F6: =F5*(1-Assumptions!$B$27) | G6: =G5*(1-Assumptions!$B$27) | H6: =H5*(1-Assumptions!$B$27) | I6: =I5*(1-Assumptions!$B$27)
A8: Accounts Receivable | B8: =B5*Assumptions!$B$70/365 | C8: =C5*Assumptions!$B$70/365 | D8: =D5*Assumptions!$B$70/365 | E8: =E5*Assumptions!$B$70/365 | F8: =F5*Assumptions!$B$70/365 | G8: =G5*Assumptions!$B$70/365 | H8: =H5*Assumptions!$B$70/365 | I8: =I5*Assumptions!$B$70/365
A9: Inventory | B9: =B6*Assumptions!$B$71/365 | C9: =C6*Assumptions!$B$71/365 | D9: =D6*Assumptions!$B$71/365 | E9: =E6*Assumptions!$B$71/365 | F9: =F6*Assumptions!$B$71/365 | G9: =G6*Assumptions!$B$71/365 | H9: =H6*Assumptions!$B$71/365 | I9: =I6*Assumptions!$B$71/365
A10: Accounts Payable | B10: =-B6*Assumptions!$B$72/365 | C10: =-C6*Assumptions!$B$72/365 | D10: =-D6*Assumptions!$B$72/365 | E10: =-E6*Assumptions!$B$72/365 | F10: =-F6*Assumptions!$B$72/365 | G10: =-G6*Assumptions!$B$72/365 | H10: =-H6*Assumptions!$B$72/365 | I10: =-I6*Assumptions!$B$72/365
A12: Net Working Capital | B12: =B8+B9+B10 | C12: =C8+C9+C10 | D12: =D8+D9+D10 | E12: =E8+E9+E10 | F12: =F8+F9+F10 | G12: =G8+G9+G10 | H12: =H8+H9+H10 | I12: =I8+I9+I10
A13: NWC / Revenue % | B13: =B12/B5 | C13: =C12/C5 | D13: =D12/D5 | E13: =E12/E5 | F13: =F12/F5 | G13: =G12/G5 | H13: =H12/H5 | I13: =I12/I5
A14: Change in NWC (increase = cash use) | B14: n/a (no prior year) | C14: =C12-B12 | D14: =D12-C12 | E14: =E12-D12 | F14: =F12-E12 | G14: =G12-F12 | H14: =H12-G12 | I14: =I12-H12

Sheet Capex_DA
A1: Capex and Depreciation & Amortization Schedule
A2: Capex % and D&A % of revenue per Assumptions tab, Section 6 (ILLUSTRATIVE).
A4: (EUR mm) | B4: FY2023 | C4: FY2024 | D4: FY2025 | E4: FY2026E | F4: FY2027E | G4: FY2028E | H4: FY2029E | I4: FY2030E
A5: Revenue (link) | B5: =Revenue_Build!B5 | C5: =Revenue_Build!C5 | D5: =Revenue_Build!D5 | E5: =Revenue_Build!E5 | F5: =Revenue_Build!F5 | G5: =Revenue_Build!G5 | H5: =Revenue_Build!H5 | I5: =Revenue_Build!I5
A7: Capex | B7: =B5*Assumptions!$B$60 | C7: =C5*Assumptions!$B$61 | D7: =D5*Assumptions!$B$62 | E7: =E5*Assumptions!$B$63 | F7: =F5*Assumptions!$B$64 | G7: =G5*Assumptions!$B$65 | H7: =H5*Assumptions!$B$66 | I7: =I5*Assumptions!$B$67
A8: Capex % of revenue | B8: =B7/B5 | C8: =C7/C5 | D8: =D7/D5 | E8: =E7/E5 | F8: =F7/F5 | G8: =G7/G5 | H8: =H7/H5 | I8: =I7/I5
A10: D&A | B10: =B5*Assumptions!$B$59 | C10: =C5*Assumptions!$B$59 | D10: =D5*Assumptions!$B$59 | E10: =E5*Assumptions!$B$59 | F10: =F5*Assumptions!$B$59 | G10: =G5*Assumptions!$B$59 | H10: =H5*Assumptions!$B$59 | I10: =I5*Assumptions!$B$59
A11: D&A % of revenue | B11: =B10/B5 | C11: =C10/C5 | D11: =D10/D5 | E11: =E10/E5 | F11: =F10/F5 | G11: =G10/G5 | H11: =H10/H5 | I11: =I10/I5

Sheet Carveout_PnL
A1: Carve-Out P&L and Unlevered Free Cash Flow
A2: EUR mm. See Assumptions tab for all margin, cost-bridge, tax, capex and D&A inputs (ILLUSTRATIVE unless marked PUBLIC FACT).
A4: (EUR mm) | B4: FY2023 | C4: FY2024 | D4: FY2025 | E4: FY2026E | F4: FY2027E | G4: FY2028E | H4: FY2029E | I4: FY2030E
A5: Revenue | B5: =Revenue_Build!B5 | C5: =Revenue_Build!C5 | D5: =Revenue_Build!D5 | E5: =Revenue_Build!E5 | F5: =Revenue_Build!F5 | G5: =Revenue_Build!G5 | H5: =Revenue_Build!H5 | I5: =Revenue_Build!I5
A6: Revenue growth % YoY | C6: =C5/B5-1 | D6: =D5/C5-1 | E6: =E5/D5-1 | F6: =F5/E5-1 | G6: =G5/F5-1 | H6: =H5/G5-1 | I6: =I5/H5-1
A8: Gross Profit | B8: =B5*Assumptions!$B$27 | C8: =C5*Assumptions!$B$27 | D8: =D5*Assumptions!$B$27 | E8: =E5*Assumptions!$B$27 | F8: =F5*Assumptions!$B$27 | G8: =G5*Assumptions!$B$27 | H8: =H5*Assumptions!$B$27 | I8: =I5*Assumptions!$B$27
A9: Gross margin % | B9: =Assumptions!$B$27 | C9: =Assumptions!$B$27 | D9: =Assumptions!$B$27 | E9: =Assumptions!$B$27 | F9: =Assumptions!$B$27 | G9: =Assumptions!$B$27 | H9: =Assumptions!$B$27 | I9: =Assumptions!$B$27
A11: EBITDA | B11: =B5*Assumptions!$B$28 | C11: =C5*Assumptions!$B$29 | D11: =D5*Assumptions!$B$30 | E11: =E5*Assumptions!$B$31 | F11: =F5*Assumptions!$B$32 | G11: =G5*Assumptions!$B$33 | H11: =H5*Assumptions!$B$34 | I11: =I5*Assumptions!$B$35
A12: EBITDA margin % | B12: =Assumptions!$B$28 | C12: =Assumptions!$B$29 | D12: =Assumptions!$B$30 | E12: =Assumptions!$B$31 | F12: =Assumptions!$B$32 | G12: =Assumptions!$B$33 | H12: =Assumptions!$B$34 | I12: =Assumptions!$B$35
A14: Operating expenses — carve-out mechanics
A15: TSA costs | B15: =-B5*Assumptions!$B$38 | C15: =-C5*Assumptions!$B$39 | D15: =-D5*Assumptions!$B$40 | E15: =-E5*Assumptions!$B$41 | F15: =-F5*Assumptions!$B$42 | G15: =-G5*Assumptions!$B$43 | H15: =-H5*Assumptions!$B$44 | I15: =-I5*Assumptions!$B$45
A16: Stranded / standalone replacement costs | B16: =-B5*Assumptions!$B$47 | C16: =-C5*Assumptions!$B$48 | D16: =-D5*Assumptions!$B$49 | E16: =-E5*Assumptions!$B$50 | F16: =-F5*Assumptions!$B$51 | G16: =-G5*Assumptions!$B$52 | H16: =-H5*Assumptions!$B$53 | I16: =-I5*Assumptions!$B$54
A17: Standalone operating expenses (plug: Gross Profit less EBITDA less items above) | B17: =-(B8-B11+B15+B16) | C17: =-(C8-C11+C15+C16) | D17: =-(D8-D11+D15+D16) | E17: =-(E8-E11+E15+E16) | F17: =-(F8-F11+F15+F16) | G17: =-(G8-G11+G15+G16) | H17: =-(H8-H11+H15+H16) | I17: =-(I8-I11+I15+I16)
A18: Check: Gross Profit + Opex items = EBITDA | B18: =B8+B15+B16+B17-B11 | C18: =C8+C15+C16+C17-C11 | D18: =D8+D15+D16+D17-D11 | E18: =E8+E15+E16+E17-E11 | F18: =F8+F15+F16+F17-F11 | G18: =G8+G15+G16+G17-G11 | H18: =H8+H15+H16+H17-H11 | I18: =I8+I15+I16+I17-I11
A20: D&A | B20: =-Capex_DA!B10 | C20: =-Capex_DA!C10 | D20: =-Capex_DA!D10 | E20: =-Capex_DA!E10 | F20: =-Capex_DA!F10 | G20: =-Capex_DA!G10 | H20: =-Capex_DA!H10 | I20: =-Capex_DA!I10
A21: EBIT | B21: =B11+B20 | C21: =C11+C20 | D21: =D11+D20 | E21: =E11+E20 | F21: =F11+F20 | G21: =G11+G20 | H21: =H11+H20 | I21: =I11+I20
A23: Cash taxes (= EBIT x blended effective tax rate; simplified, no timing differences) | B23: =-MAX(B21,0)*Assumptions!$B$79 | C23: =-MAX(C21,0)*Assumptions!$B$79 | D23: =-MAX(D21,0)*Assumptions!$B$79 | E23: =-MAX(E21,0)*Assumptions!$B$79 | F23: =-MAX(F21,0)*Assumptions!$B$79 | G23: =-MAX(G21,0)*Assumptions!$B$79 | H23: =-MAX(H21,0)*Assumptions!$B$79 | I23: =-MAX(I21,0)*Assumptions!$B$79
A24: Capex | B24: =-Capex_DA!B7 | C24: =-Capex_DA!C7 | D24: =-Capex_DA!D7 | E24: =-Capex_DA!E7 | F24: =-Capex_DA!F7 | G24: =-Capex_DA!G7 | H24: =-Capex_DA!H7 | I24: =-Capex_DA!I7
A25: Change in NWC (increase = cash outflow) | B25: n/a | C25: =-Working_Capital!C14 | D25: =-Working_Capital!D14 | E25: =-Working_Capital!E14 | F25: =-Working_Capital!F14 | G25: =-Working_Capital!G14 | H25: =-Working_Capital!H14 | I25: =-Working_Capital!I14
A26: One-time separation costs (FY2026E only, illustrative, pre-tax) | B26: 0 | C26: 0 | D26: 0 | E26: =-Assumptions!$B$56 | F26: 0 | G26: 0 | H26: 0 | I26: 0
A28: Unlevered Free Cash Flow | B28: n/a | C28: =C21+C23+C20*-1+C24+C25+C26 | D28: =D21+D23+D20*-1+D24+D25+D26 | E28: =E21+E23+E20*-1+E24+E25+E26 | F28: =F21+F23+F20*-1+F24+F25+F26 | G28: =G21+G23+G20*-1+G24+G25+G26 | H28: =H21+H23+H20*-1+H24+H25+H26 | I28: =I21+I23+I20*-1+I24+I25+I26

Sheet DCF_Valuation
A1: DCF Valuation — Unlevered Free Cash Flow
A2: Discounts FY2026E-FY2030E unlevered FCF from Carveout_PnL at the WACC derived on the Assumptions tab. Enterprise Value only — see equity bridge note below for the debt/cash disclosure limitation.
A4: (EUR mm) | B4: FY2026E | C4: FY2027E | D4: FY2028E | E4: FY2029E | F4: FY2030E
A5: Unlevered Free Cash Flow | B5: =Carveout_PnL!E28 | C5: =Carveout_PnL!F28 | D5: =Carveout_PnL!G28 | E5: =Carveout_PnL!H28 | F5: =Carveout_PnL!I28
A6: Period (t) | B6: 1 | C6: 2 | D6: 3 | E6: 4 | F6: 5
A7: Discount factor @ WACC | B7: =1/(1+Assumptions!$B$90)^B6 | C7: =1/(1+Assumptions!$B$90)^C6 | D7: =1/(1+Assumptions!$B$90)^D6 | E7: =1/(1+Assumptions!$B$90)^E6 | F7: =1/(1+Assumptions!$B$90)^F6
A8: PV of FCF | B8: =B5*B7 | C8: =C5*C7 | D8: =D5*D7 | E8: =E5*E7 | F8: =F5*F7
A10: Terminal Value (Gordon Growth, on FY2030E FCF) | F10: =E5*(1+Assumptions!$B$92)/(Assumptions!$B$90-Assumptions!$B$92)
A11: PV of Terminal Value | F11: =F10*F7
A13: Sum of PV of FCF (FY2026E-FY2030E) | B13: =SUM(B8:F8)
A14: PV of Terminal Value | B14: =F11
A15: Enterprise Value (EUR mm) | B15: =B13+B14
A16: TV as % of Enterprise Value | B16: =B14/B15
A18: Implied EV / FY2026E Revenue | B18: =B15/Carveout_PnL!E5
A19: Implied EV / FY2026E EBITDA | B19: =B15/Carveout_PnL!E11
A21: Equity Bridge
A22: Enterprise Value | B22: =B15
A23: Less: Debt (asset-level, SEA carve-out) | B23: N/A — not publicly disclosed
A24: Plus: Cash (asset-level, SEA carve-out) | B24: N/A — not publicly disclosed
A25: Equity Value | B25: Cannot be calculated — see limitation note below
A27: LIMITATION: AkzoNobel does not publicly disclose asset-level (SEA decorative carve-out) debt or cash balances — these exist only at the consolidated group level and are not allocable to this perimeter without confidential carve-out balance sheet data. The Enterprise Value above is therefore presented as the primary valuation output; no Equity Value can be responsibly calculated from public information.
A30: Sensitivity: Enterprise Value (EUR mm) — WACC x Terminal Growth
A31: WACC \ g | B31: =Assumptions!$B$92+(-0.01) | C31: =Assumptions!$B$92+(-0.005) | D31: =Assumptions!$B$92+(0.0) | E31: =Assumptions!$B$92+(0.005) | F31: =Assumptions!$B$92+(0.01)
A32: =Assumptions!$B$90+(-0.01) | B32: =B$5/(1+$A32)^1+C$5/(1+$A32)^2+D$5/(1+$A32)^3+E$5/(1+$A32)^4+F$5/(1+$A32)^5+(F$5*(1+B$31)/($A32-B$31))/(1+$A32)^5 | C32: =B$5/(1+$A32)^1+C$5/(1+$A32)^2+D$5/(1+$A32)^3+E$5/(1+$A32)^4+F$5/(1+$A32)^5+(F$5*(1+C$31)/($A32-C$31))/(1+$A32)^5 | D32: =B$5/(1+$A32)^1+C$5/(1+$A32)^2+D$5/(1+$A32)^3+E$5/(1+$A32)^4+F$5/(1+$A32)^5+(F$5*(1+D$31)/($A32-D$31))/(1+$A32)^5 | E32: =B$5/(1+$A32)^1+C$5/(1+$A32)^2+D$5/(1+$A32)^3+E$5/(1+$A32)^4+F$5/(1+$A32)^5+(F$5*(1+E$31)/($A32-E$31))/(1+$A32)^5 | F32: =B$5/(1+$A32)^1+C$5/(1+$A32)^2+D$5/(1+$A32)^3+E$5/(1+$A32)^4+F$5/(1+$A32)^5+(F$5*(1+F$31)/($A32-F$31))/(1+$A32)^5
A33: =Assumptions!$B$90+(-0.005) | B33: =B$5/(1+$A33)^1+C$5/(1+$A33)^2+D$5/(1+$A33)^3+E$5/(1+$A33)^4+F$5/(1+$A33)^5+(F$5*(1+B$31)/($A33-B$31))/(1+$A33)^5 | C33: =B$5/(1+$A33)^1+C$5/(1+$A33)^2+D$5/(1+$A33)^3+E$5/(1+$A33)^4+F$5/(1+$A33)^5+(F$5*(1+C$31)/($A33-C$31))/(1+$A33)^5 | D33: =B$5/(1+$A33)^1+C$5/(1+$A33)^2+D$5/(1+$A33)^3+E$5/(1+$A33)^4+F$5/(1+$A33)^5+(F$5*(1+D$31)/($A33-D$31))/(1+$A33)^5 | E33: =B$5/(1+$A33)^1+C$5/(1+$A33)^2+D$5/(1+$A33)^3+E$5/(1+$A33)^4+F$5/(1+$A33)^5+(F$5*(1+E$31)/($A33-E$31))/(1+$A33)^5 | F33: =B$5/(1+$A33)^1+C$5/(1+$A33)^2+D$5/(1+$A33)^3+E$5/(1+$A33)^4+F$5/(1+$A33)^5+(F$5*(1+F$31)/($A33-F$31))/(1+$A33)^5
A34: =Assumptions!$B$90+(0.0) | B34: =B$5/(1+$A34)^1+C$5/(1+$A34)^2+D$5/(1+$A34)^3+E$5/(1+$A34)^4+F$5/(1+$A34)^5+(F$5*(1+B$31)/($A34-B$31))/(1+$A34)^5 | C34: =B$5/(1+$A34)^1+C$5/(1+$A34)^2+D$5/(1+$A34)^3+E$5/(1+$A34)^4+F$5/(1+$A34)^5+(F$5*(1+C$31)/($A34-C$31))/(1+$A34)^5 | D34: =B$5/(1+$A34)^1+C$5/(1+$A34)^2+D$5/(1+$A34)^3+E$5/(1+$A34)^4+F$5/(1+$A34)^5+(F$5*(1+D$31)/($A34-D$31))/(1+$A34)^5 | E34: =B$5/(1+$A34)^1+C$5/(1+$A34)^2+D$5/(1+$A34)^3+E$5/(1+$A34)^4+F$5/(1+$A34)^5+(F$5*(1+E$31)/($A34-E$31))/(1+$A34)^5 | F34: =B$5/(1+$A34)^1+C$5/(1+$A34)^2+D$5/(1+$A34)^3+E$5/(1+$A34)^4+F$5/(1+$A34)^5+(F$5*(1+F$31)/($A34-F$31))/(1+$A34)^5
A35: =Assumptions!$B$90+(0.005) | B35: =B$5/(1+$A35)^1+C$5/(1+$A35)^2+D$5/(1+$A35)^3+E$5/(1+$A35)^4+F$5/(1+$A35)^5+(F$5*(1+B$31)/($A35-B$31))/(1+$A35)^5 | C35: =B$5/(1+$A35)^1+C$5/(1+$A35)^2+D$5/(1+$A35)^3+E$5/(1+$A35)^4+F$5/(1+$A35)^5+(F$5*(1+C$31)/($A35-C$31))/(1+$A35)^5 | D35: =B$5/(1+$A35)^1+C$5/(1+$A35)^2+D$5/(1+$A35)^3+E$5/(1+$A35)^4+F$5/(1+$A35)^5+(F$5*(1+D$31)/($A35-D$31))/(1+$A35)^5 | E35: =B$5/(1+$A35)^1+C$5/(1+$A35)^2+D$5/(1+$A35)^3+E$5/(1+$A35)^4+F$5/(1+$A35)^5+(F$5*(1+E$31)/($A35-E$31))/(1+$A35)^5 | F35: =B$5/(1+$A35)^1+C$5/(1+$A35)^2+D$5/(1+$A35)^3+E$5/(1+$A35)^4+F$5/(1+$A35)^5+(F$5*(1+F$31)/($A35-F$31))/(1+$A35)^5
A36: =Assumptions!$B$90+(0.01) | B36: =B$5/(1+$A36)^1+C$5/(1+$A36)^2+D$5/(1+$A36)^3+E$5/(1+$A36)^4+F$5/(1+$A36)^5+(F$5*(1+B$31)/($A36-B$31))/(1+$A36)^5 | C36: =B$5/(1+$A36)^1+C$5/(1+$A36)^2+D$5/(1+$A36)^3+E$5/(1+$A36)^4+F$5/(1+$A36)^5+(F$5*(1+C$31)/($A36-C$31))/(1+$A36)^5 | D36: =B$5/(1+$A36)^1+C$5/(1+$A36)^2+D$5/(1+$A36)^3+E$5/(1+$A36)^4+F$5/(1+$A36)^5+(F$5*(1+D$31)/($A36-D$31))/(1+$A36)^5 | E36: =B$5/(1+$A36)^1+C$5/(1+$A36)^2+D$5/(1+$A36)^3+E$5/(1+$A36)^4+F$5/(1+$A36)^5+(F$5*(1+E$31)/($A36-E$31))/(1+$A36)^5 | F36: =B$5/(1+$A36)^1+C$5/(1+$A36)^2+D$5/(1+$A36)^3+E$5/(1+$A36)^4+F$5/(1+$A36)^5+(F$5*(1+F$31)/($A36-F$31))/(1+$A36)^5

Sheet Sources
A1: Source ID | B1: Source | C1: URL | D1: Used For
A2: SRC-001 | B2: ION Analytics / Mergermarket, 'AkzoNobel taps Goldman Sachs for sale of Southeast Asia paints assets' | C2: https://ionanalytics.com/insights/mergermarket/akzonobel-taps-goldman-sachs-for-sale-of-southeast-asia-paints-assets/ | D2: Revenue anchor (EUR 300m), country scope, ASEAN market size/CAGR basis
A3: SRC-013 | B3: PCI Magazine, '2026 Global Top 10: No. 3, AkzoNobel' (FY2025 segment results) | C3: https://www.pcimag.com/articles/114754-2026-global-top-10-no-3-akzonobel | D3: Group Decorative Paints EBITDA margin proxy (FY2024 14.2%, FY2025 15.8%)
A4: SRC-015 | B4: AkzoNobel FY2025/FY2024 results releases (Decorative Paints segment margin) | C4: https://www.akzonobel.com/en/media/media-releases/q4-2025 | D4: Corroborates Group Decorative Paints EBITDA margin trend
A5: SRC-016 | B5: OECD Corporate Tax Statistics 2026 / Trading Economics / PwC Tax Summaries / Thaicore | C5: https://www.oecd.org/en/publications/corporate-tax-statistics-2026_73af6222-en.html | D5: Statutory CIT rates: Indonesia 22%, Thailand 20%, Malaysia 24%, Vietnam 20%
A6: SRC-017 | B6: Multiples.vc / market commentary — Asian Paints, Nippon Paint, Kansai Paint EBITDA margins | C6: https://multiples.vc/public-comps/nippon-paint-valuation-multiples | D6: Peer EBITDA margin benchmarks used to justify forward margin ramp assumption
